2022-02-25 12:48:12,315 INFO    MainThread:9740 [internal.py:wandb_internal():90] W&B internal server running at pid: 9740, started at: 2022-02-25 12:48:12.314629
2022-02-25 12:48:12,319 DEBUG   HandlerThread:9740 [handler.py:handle_request():130] handle_request: check_version
2022-02-25 12:48:12,319 INFO    WriterThread:9740 [datastore.py:open_for_write():77] open: /home/simon/CDE_UBS/thesis/template/wandb/run-20220225_124810-t5kfz57r/run-t5kfz57r.wandb
2022-02-25 12:48:12,320 DEBUG   SenderThread:9740 [sender.py:send():234] send: header
2022-02-25 12:48:12,320 DEBUG   SenderThread:9740 [sender.py:send_request():248] send_request: check_version
2022-02-25 12:48:12,451 DEBUG   SenderThread:9740 [sender.py:send():234] send: run
2022-02-25 12:48:42,451 DEBUG   HandlerThread:9740 [handler.py:handle_request():130] handle_request: shutdown
2022-02-25 12:48:42,452 INFO    HandlerThread:9740 [handler.py:finish():731] shutting down handler
2022-02-25 12:48:42,460 INFO    WriterThread:9740 [datastore.py:close():281] close: /home/simon/CDE_UBS/thesis/template/wandb/run-20220225_124810-t5kfz57r/run-t5kfz57r.wandb
2022-02-25 12:48:46,158 ERROR   SenderThread:9740 [retry.py:__call__():126] Retry attempt failed:
Traceback (most recent call last):
  File "/home/simon/.local/lib/python3.7/site-packages/urllib3/connectionpool.py", line 445, in _make_request
    six.raise_from(e, None)
  File "<string>", line 3, in raise_from
  File "/home/simon/.local/lib/python3.7/site-packages/urllib3/connectionpool.py", line 440, in _make_request
    httplib_response = conn.getresponse()
  File "/anaconda/lib/python3.7/http/client.py", line 1344, in getresponse
    response.begin()
  File "/anaconda/lib/python3.7/http/client.py", line 306, in begin
    version, status, reason = self._read_status()
  File "/anaconda/lib/python3.7/http/client.py", line 267, in _read_status
    line = str(self.fp.readline(_MAXLINE + 1), "iso-8859-1")
  File "/anaconda/lib/python3.7/socket.py", line 589, in readinto
    return self._sock.recv_into(b)
  File "/anaconda/lib/python3.7/ssl.py", line 1071, in recv_into
    return self.read(nbytes, buffer)
  File "/anaconda/lib/python3.7/ssl.py", line 929, in read
    return self._sslobj.read(len, buffer)
socket.timeout: The read operation timed out

During handling of the above exception, another exception occurred:

Traceback (most recent call last):
  File "/home/simon/.local/lib/python3.7/site-packages/requests/adapters.py", line 449, in send
    timeout=timeout
  File "/home/simon/.local/lib/python3.7/site-packages/urllib3/connectionpool.py", line 756, in urlopen
    method, url, error=e, _pool=self, _stacktrace=sys.exc_info()[2]
  File "/home/simon/.local/lib/python3.7/site-packages/urllib3/util/retry.py", line 532, in increment
    raise six.reraise(type(error), error, _stacktrace)
  File "/home/simon/.local/lib/python3.7/site-packages/urllib3/packages/six.py", line 770, in reraise
    raise value
  File "/home/simon/.local/lib/python3.7/site-packages/urllib3/connectionpool.py", line 706, in urlopen
    chunked=chunked,
  File "/home/simon/.local/lib/python3.7/site-packages/urllib3/connectionpool.py", line 447, in _make_request
    self._raise_timeout(err=e, url=url, timeout_value=read_timeout)
  File "/home/simon/.local/lib/python3.7/site-packages/urllib3/connectionpool.py", line 337, in _raise_timeout
    self, url, "Read timed out. (read timeout=%s)" % timeout_value
urllib3.exceptions.ReadTimeoutError: HTTPSConnectionPool(host='api.wandb.ai', port=443): Read timed out. (read timeout=10)

During handling of the above exception, another exception occurred:

Traceback (most recent call last):
  File "/home/simon/.local/lib/python3.7/site-packages/wandb/sdk/lib/retry.py", line 102, in __call__
    result = self._call_fn(*args, **kwargs)
  File "/home/simon/.local/lib/python3.7/site-packages/wandb/sdk/internal/internal_api.py", line 141, in execute
    return self.client.execute(*args, **kwargs)
  File "/home/simon/.local/lib/python3.7/site-packages/wandb/vendor/gql-0.2.0/gql/client.py", line 52, in execute
    result = self._get_result(document, *args, **kwargs)
  File "/home/simon/.local/lib/python3.7/site-packages/wandb/vendor/gql-0.2.0/gql/client.py", line 60, in _get_result
    return self.transport.execute(document, *args, **kwargs)
  File "/home/simon/.local/lib/python3.7/site-packages/wandb/vendor/gql-0.2.0/gql/transport/requests.py", line 38, in execute
    request = requests.post(self.url, **post_args)
  File "/home/simon/.local/lib/python3.7/site-packages/requests/api.py", line 117, in post
    return request('post', url, data=data, json=json, **kwargs)
  File "/home/simon/.local/lib/python3.7/site-packages/requests/api.py", line 61, in request
    return session.request(method=method, url=url, **kwargs)
  File "/home/simon/.local/lib/python3.7/site-packages/requests/sessions.py", line 542, in request
    resp = self.send(prep, **send_kwargs)
  File "/home/simon/.local/lib/python3.7/site-packages/requests/sessions.py", line 655, in send
    r = adapter.send(request, **kwargs)
  File "/home/simon/.local/lib/python3.7/site-packages/requests/adapters.py", line 529, in send
    raise ReadTimeout(e, request=request)
requests.exceptions.ReadTimeout: HTTPSConnectionPool(host='api.wandb.ai', port=443): Read timed out. (read timeout=10)
2022-02-25 12:49:09,942 ERROR   SenderThread:9740 [internal_api.py:execute():144] 500 response executing GraphQL.
2022-02-25 12:49:09,942 ERROR   SenderThread:9740 [internal_api.py:execute():145] {"error":"Error 1040: Too many connections"}
2022-02-25 12:49:29,001 ERROR   SenderThread:9740 [internal_api.py:execute():144] 500 response executing GraphQL.
2022-02-25 12:49:29,001 ERROR   SenderThread:9740 [internal_api.py:execute():145] {"error":"Error 1040: Too many connections"}
2022-02-25 12:50:09,160 INFO    SenderThread:9740 [dir_watcher.py:__init__():169] watching files in: /home/simon/CDE_UBS/thesis/template/wandb/run-20220225_124810-t5kfz57r/files
2022-02-25 12:50:09,160 INFO    SenderThread:9740 [sender.py:_start_run_threads():807] run started: t5kfz57r with start time 1645789690
2022-02-25 12:50:09,160 INFO    SenderThread:9740 [sender.py:finish():1070] shutting down sender
2022-02-25 12:50:09,160 INFO    SenderThread:9740 [dir_watcher.py:finish():283] shutting down directory watcher
2022-02-25 12:50:10,160 INFO    SenderThread:9740 [dir_watcher.py:finish():313] scan: /home/simon/CDE_UBS/thesis/template/wandb/run-20220225_124810-t5kfz57r/files
2022-02-25 12:50:10,160 INFO    SenderThread:9740 [dir_watcher.py:finish():327] scan save: /home/simon/CDE_UBS/thesis/template/wandb/run-20220225_124810-t5kfz57r/files/config.yaml config.yaml
2022-02-25 12:50:10,161 INFO    SenderThread:9740 [file_pusher.py:finish():177] shutting down file pusher
2022-02-25 12:50:10,161 INFO    SenderThread:9740 [file_pusher.py:join():182] waiting for file pusher
2022-02-25 12:50:10,718 INFO    Thread-10 :9740 [upload_job.py:push():137] Uploaded file /home/simon/CDE_UBS/thesis/template/wandb/run-20220225_124810-t5kfz57r/files/config.yaml
2022-02-25 12:50:11,338 INFO    MainThread:9740 [internal.py:handle_exit():77] Internal process exited
