2022-02-25 12:48:10,498 INFO    MainThread:9697 [wandb_setup.py:_flush():71] setting env: {}
2022-02-25 12:48:10,498 INFO    MainThread:9697 [wandb_setup.py:_flush():71] setting login settings: {}
2022-02-25 12:48:10,498 INFO    MainThread:9697 [wandb_init.py:_log_setup():371] Logging user logs to /home/simon/CDE_UBS/thesis/template/wandb/run-20220225_124810-t5kfz57r/logs/debug.log
2022-02-25 12:48:10,498 INFO    MainThread:9697 [wandb_init.py:_log_setup():372] Logging internal logs to /home/simon/CDE_UBS/thesis/template/wandb/run-20220225_124810-t5kfz57r/logs/debug-internal.log
2022-02-25 12:48:10,499 INFO    MainThread:9697 [wandb_init.py:_jupyter_setup():321] configuring jupyter hooks <wandb.sdk.wandb_init._WandbInit object at 0x7f66be33aad0>
2022-02-25 12:48:10,499 INFO    MainThread:9697 [wandb_init.py:init():404] calling init triggers
2022-02-25 12:48:10,499 INFO    MainThread:9697 [wandb_init.py:init():411] wandb.init called with sweep_config: {}
config: {}
2022-02-25 12:48:10,499 INFO    MainThread:9697 [wandb_init.py:init():460] starting backend
2022-02-25 12:48:10,499 INFO    MainThread:9697 [backend.py:_multiprocessing_setup():101] multiprocessing start_methods=fork,spawn,forkserver, using: spawn
2022-02-25 12:48:10,546 INFO    MainThread:9697 [backend.py:ensure_launched():216] starting backend process...
2022-02-25 12:48:10,581 INFO    MainThread:9697 [backend.py:ensure_launched():222] started backend process with pid: 9740
2022-02-25 12:48:10,583 INFO    MainThread:9697 [wandb_init.py:init():469] backend started and connected
2022-02-25 12:48:10,618 INFO    MainThread:9697 [wandb_run.py:_label_probe_notebook():911] probe notebook
2022-02-25 12:48:10,621 INFO    MainThread:9697 [wandb_run.py:_label_probe_notebook():921] Unable to probe notebook: 'NoneType' object has no attribute 'get'
2022-02-25 12:48:10,621 INFO    MainThread:9697 [wandb_init.py:init():533] updated telemetry
2022-02-25 12:48:10,709 INFO    MainThread:9697 [wandb_init.py:init():563] communicating current version
2022-02-25 12:48:12,447 INFO    MainThread:9697 [wandb_init.py:init():568] got version response upgrade_message: "wandb version 0.12.10 is available!  To upgrade, please run:\n $ pip install wandb --upgrade"

2022-02-25 12:48:12,448 INFO    MainThread:9697 [wandb_init.py:init():578] communicating run to backend with 30 second timeout
2022-02-25 12:48:42,450 INFO    MainThread:9697 [interface_shared.py:_communicate_run():313] couldn't get run from backend
2022-02-25 12:48:42,450 ERROR   MainThread:9697 [wandb_init.py:init():583] backend process timed out
2022-02-25 12:48:42,450 ERROR   MainThread:9697 [wandb_init.py:init():592] encountered error: Error communicating with wandb process
try: wandb.init(settings=wandb.Settings(start_method='fork'))
or:  wandb.init(settings=wandb.Settings(start_method='thread'))
For more info see: https://docs.wandb.ai/library/init#init-start-error
2022-02-25 12:49:08,735 ERROR   Thread-4  :9697 [retry.py:__call__():126] Retry attempt failed:
Traceback (most recent call last):
  File "/home/simon/.local/lib/python3.7/site-packages/urllib3/connectionpool.py", line 445, in _make_request
    six.raise_from(e, None)
  File "<string>", line 3, in raise_from
  File "/home/simon/.local/lib/python3.7/site-packages/urllib3/connectionpool.py", line 440, in _make_request
    httplib_response = conn.getresponse()
  File "/anaconda/lib/python3.7/http/client.py", line 1344, in getresponse
    response.begin()
  File "/anaconda/lib/python3.7/http/client.py", line 306, in begin
    version, status, reason = self._read_status()
  File "/anaconda/lib/python3.7/http/client.py", line 267, in _read_status
    line = str(self.fp.readline(_MAXLINE + 1), "iso-8859-1")
  File "/anaconda/lib/python3.7/socket.py", line 589, in readinto
    return self._sock.recv_into(b)
  File "/anaconda/lib/python3.7/ssl.py", line 1071, in recv_into
    return self.read(nbytes, buffer)
  File "/anaconda/lib/python3.7/ssl.py", line 929, in read
    return self._sslobj.read(len, buffer)
socket.timeout: The read operation timed out

During handling of the above exception, another exception occurred:

Traceback (most recent call last):
  File "/home/simon/.local/lib/python3.7/site-packages/requests/adapters.py", line 449, in send
    timeout=timeout
  File "/home/simon/.local/lib/python3.7/site-packages/urllib3/connectionpool.py", line 756, in urlopen
    method, url, error=e, _pool=self, _stacktrace=sys.exc_info()[2]
  File "/home/simon/.local/lib/python3.7/site-packages/urllib3/util/retry.py", line 532, in increment
    raise six.reraise(type(error), error, _stacktrace)
  File "/home/simon/.local/lib/python3.7/site-packages/urllib3/packages/six.py", line 770, in reraise
    raise value
  File "/home/simon/.local/lib/python3.7/site-packages/urllib3/connectionpool.py", line 706, in urlopen
    chunked=chunked,
  File "/home/simon/.local/lib/python3.7/site-packages/urllib3/connectionpool.py", line 447, in _make_request
    self._raise_timeout(err=e, url=url, timeout_value=read_timeout)
  File "/home/simon/.local/lib/python3.7/site-packages/urllib3/connectionpool.py", line 337, in _raise_timeout
    self, url, "Read timed out. (read timeout=%s)" % timeout_value
urllib3.exceptions.ReadTimeoutError: HTTPSConnectionPool(host='api.wandb.ai', port=443): Read timed out. (read timeout=10)

During handling of the above exception, another exception occurred:

Traceback (most recent call last):
  File "/home/simon/.local/lib/python3.7/site-packages/wandb/sdk/lib/retry.py", line 102, in __call__
    result = self._call_fn(*args, **kwargs)
  File "/home/simon/.local/lib/python3.7/site-packages/wandb/sdk/internal/internal_api.py", line 141, in execute
    return self.client.execute(*args, **kwargs)
  File "/home/simon/.local/lib/python3.7/site-packages/wandb/vendor/gql-0.2.0/gql/client.py", line 52, in execute
    result = self._get_result(document, *args, **kwargs)
  File "/home/simon/.local/lib/python3.7/site-packages/wandb/vendor/gql-0.2.0/gql/client.py", line 60, in _get_result
    return self.transport.execute(document, *args, **kwargs)
  File "/home/simon/.local/lib/python3.7/site-packages/wandb/vendor/gql-0.2.0/gql/transport/requests.py", line 38, in execute
    request = requests.post(self.url, **post_args)
  File "/home/simon/.local/lib/python3.7/site-packages/requests/api.py", line 117, in post
    return request('post', url, data=data, json=json, **kwargs)
  File "/home/simon/.local/lib/python3.7/site-packages/requests/api.py", line 61, in request
    return session.request(method=method, url=url, **kwargs)
  File "/home/simon/.local/lib/python3.7/site-packages/requests/sessions.py", line 542, in request
    resp = self.send(prep, **send_kwargs)
  File "/home/simon/.local/lib/python3.7/site-packages/requests/sessions.py", line 655, in send
    r = adapter.send(request, **kwargs)
  File "/home/simon/.local/lib/python3.7/site-packages/requests/adapters.py", line 529, in send
    raise ReadTimeout(e, request=request)
requests.exceptions.ReadTimeout: HTTPSConnectionPool(host='api.wandb.ai', port=443): Read timed out. (read timeout=10)
2022-02-25 12:49:15,986 ERROR   Thread-4  :9697 [internal_api.py:execute():144] 500 response executing GraphQL.
2022-02-25 12:49:15,986 ERROR   Thread-4  :9697 [internal_api.py:execute():145] {"error":"Error 1040: Too many connections"}
2022-02-25 12:49:25,118 ERROR   Thread-4  :9697 [internal_api.py:execute():144] 500 response executing GraphQL.
2022-02-25 12:49:25,119 ERROR   Thread-4  :9697 [internal_api.py:execute():145] {"error":"Error 1040: Too many connections"}
2022-02-25 12:49:43,581 ERROR   Thread-4  :9697 [internal_api.py:execute():144] 500 response executing GraphQL.
2022-02-25 12:49:43,581 ERROR   Thread-4  :9697 [internal_api.py:execute():145] {"error":"Error 1040: Too many connections"}
2022-02-25 12:49:51,800 WARNING MainThread:9697 [wandb_init.py:init():952] interrupted
Traceback (most recent call last):
  File "/home/simon/.local/lib/python3.7/site-packages/wandb/sdk/wandb_init.py", line 931, in init
    run = wi.init()
  File "/home/simon/.local/lib/python3.7/site-packages/wandb/sdk/wandb_init.py", line 596, in init
    backend.cleanup()
  File "/home/simon/.local/lib/python3.7/site-packages/wandb/sdk/backend/backend.py", line 247, in cleanup
    self.wandb_process.join()
  File "/anaconda/lib/python3.7/multiprocessing/process.py", line 140, in join
    res = self._popen.wait(timeout)
  File "/anaconda/lib/python3.7/multiprocessing/popen_fork.py", line 48, in wait
    return self.poll(os.WNOHANG if timeout == 0.0 else 0)
  File "/anaconda/lib/python3.7/multiprocessing/popen_fork.py", line 28, in poll
    pid, sts = os.waitpid(self.pid, flag)
KeyboardInterrupt
