2022-02-25 12:46:49,606 INFO    MainThread:9608 [wandb_setup.py:_flush():71] setting env: {}
2022-02-25 12:46:49,606 INFO    MainThread:9608 [wandb_setup.py:_flush():71] setting login settings: {}
2022-02-25 12:46:49,606 INFO    MainThread:9608 [wandb_init.py:_log_setup():371] Logging user logs to /home/simon/CDE_UBS/thesis/template/wandb/run-20220225_124649-2chzy5bv/logs/debug.log
2022-02-25 12:46:49,606 INFO    MainThread:9608 [wandb_init.py:_log_setup():372] Logging internal logs to /home/simon/CDE_UBS/thesis/template/wandb/run-20220225_124649-2chzy5bv/logs/debug-internal.log
2022-02-25 12:46:49,607 INFO    MainThread:9608 [wandb_init.py:_jupyter_setup():321] configuring jupyter hooks <wandb.sdk.wandb_init._WandbInit object at 0x7f38ca7ca690>
2022-02-25 12:46:49,607 INFO    MainThread:9608 [wandb_init.py:init():404] calling init triggers
2022-02-25 12:46:49,608 INFO    MainThread:9608 [wandb_init.py:init():411] wandb.init called with sweep_config: {}
config: {}
2022-02-25 12:46:49,608 INFO    MainThread:9608 [wandb_init.py:init():460] starting backend
2022-02-25 12:46:49,608 INFO    MainThread:9608 [backend.py:_multiprocessing_setup():101] multiprocessing start_methods=fork,spawn,forkserver, using: spawn
2022-02-25 12:46:49,666 INFO    MainThread:9608 [backend.py:ensure_launched():216] starting backend process...
2022-02-25 12:46:49,721 INFO    MainThread:9608 [backend.py:ensure_launched():222] started backend process with pid: 9652
2022-02-25 12:46:49,723 INFO    MainThread:9608 [wandb_init.py:init():469] backend started and connected
2022-02-25 12:46:49,773 INFO    MainThread:9608 [wandb_run.py:_label_probe_notebook():911] probe notebook
2022-02-25 12:46:49,776 INFO    MainThread:9608 [wandb_run.py:_label_probe_notebook():921] Unable to probe notebook: 'NoneType' object has no attribute 'get'
2022-02-25 12:46:49,776 INFO    MainThread:9608 [wandb_init.py:init():533] updated telemetry
2022-02-25 12:46:49,887 INFO    MainThread:9608 [wandb_init.py:init():563] communicating current version
2022-02-25 12:46:51,658 INFO    MainThread:9608 [wandb_init.py:init():568] got version response upgrade_message: "wandb version 0.12.10 is available!  To upgrade, please run:\n $ pip install wandb --upgrade"

2022-02-25 12:46:51,660 INFO    MainThread:9608 [wandb_init.py:init():578] communicating run to backend with 30 second timeout
2022-02-25 12:46:56,043 ERROR   Thread-4  :9608 [internal_api.py:execute():144] 500 response executing GraphQL.
2022-02-25 12:46:56,044 ERROR   Thread-4  :9608 [internal_api.py:execute():145] {"error":"Error 1040: Too many connections"}
2022-02-25 12:47:01,446 ERROR   Thread-4  :9608 [internal_api.py:execute():144] 500 response executing GraphQL.
2022-02-25 12:47:01,447 ERROR   Thread-4  :9608 [internal_api.py:execute():145] {"error":"Error 1040: Too many connections"}
2022-02-25 12:47:01,447 ERROR   Thread-4  :9608 [retry.py:__call__():126] Retry attempt failed:
Traceback (most recent call last):
  File "/home/simon/.local/lib/python3.7/site-packages/wandb/sdk/lib/retry.py", line 102, in __call__
    result = self._call_fn(*args, **kwargs)
  File "/home/simon/.local/lib/python3.7/site-packages/wandb/sdk/internal/internal_api.py", line 147, in execute
    six.reraise(*sys.exc_info())
  File "/home/simon/.local/lib/python3.7/site-packages/six.py", line 719, in reraise
    raise value
  File "/home/simon/.local/lib/python3.7/site-packages/wandb/sdk/internal/internal_api.py", line 141, in execute
    return self.client.execute(*args, **kwargs)
  File "/home/simon/.local/lib/python3.7/site-packages/wandb/vendor/gql-0.2.0/gql/client.py", line 52, in execute
    result = self._get_result(document, *args, **kwargs)
  File "/home/simon/.local/lib/python3.7/site-packages/wandb/vendor/gql-0.2.0/gql/client.py", line 60, in _get_result
    return self.transport.execute(document, *args, **kwargs)
  File "/home/simon/.local/lib/python3.7/site-packages/wandb/vendor/gql-0.2.0/gql/transport/requests.py", line 39, in execute
    request.raise_for_status()
  File "/home/simon/.local/lib/python3.7/site-packages/requests/models.py", line 953, in raise_for_status
    raise HTTPError(http_error_msg, response=self)
requests.exceptions.HTTPError: 500 Server Error: Internal Server Error for url: https://api.wandb.ai/graphql
2022-02-25 12:47:21,662 INFO    MainThread:9608 [interface_shared.py:_communicate_run():313] couldn't get run from backend
2022-02-25 12:47:21,662 ERROR   MainThread:9608 [wandb_init.py:init():583] backend process timed out
2022-02-25 12:47:21,662 ERROR   MainThread:9608 [wandb_init.py:init():592] encountered error: Error communicating with wandb process
try: wandb.init(settings=wandb.Settings(start_method='fork'))
or:  wandb.init(settings=wandb.Settings(start_method='thread'))
For more info see: https://docs.wandb.ai/library/init#init-start-error
2022-02-25 12:47:26,158 ERROR   Thread-4  :9608 [internal_api.py:execute():144] 500 response executing GraphQL.
2022-02-25 12:47:26,159 ERROR   Thread-4  :9608 [internal_api.py:execute():145] {"error":"Error 1040: Too many connections"}
2022-02-25 12:47:33,022 WARNING MainThread:9608 [wandb_init.py:init():952] interrupted
Traceback (most recent call last):
  File "/home/simon/.local/lib/python3.7/site-packages/wandb/sdk/wandb_init.py", line 931, in init
    run = wi.init()
  File "/home/simon/.local/lib/python3.7/site-packages/wandb/sdk/wandb_init.py", line 596, in init
    backend.cleanup()
  File "/home/simon/.local/lib/python3.7/site-packages/wandb/sdk/backend/backend.py", line 247, in cleanup
    self.wandb_process.join()
  File "/anaconda/lib/python3.7/multiprocessing/process.py", line 140, in join
    res = self._popen.wait(timeout)
  File "/anaconda/lib/python3.7/multiprocessing/popen_fork.py", line 48, in wait
    return self.poll(os.WNOHANG if timeout == 0.0 else 0)
  File "/anaconda/lib/python3.7/multiprocessing/popen_fork.py", line 28, in poll
    pid, sts = os.waitpid(self.pid, flag)
KeyboardInterrupt
